<?xml version="1.0"?>
<robot xmlns:xacro="https://www.ros.org/wiki/xacro" name="robot">

    <material name="white">
        <color rgba="1 1 1 1"/>
    </material>

    <material name="orange">
        <color rgba="1 0.3 0.1 1"/>
    </material>

    <material name="blue">
        <color rgba="0.2 0.2 1 1"/>
    </material>

    <material name="black">
        <color rgba="0 0 0 1"/>
    </material>

    <!-- BASE LINK -->

    <link name="base_link">

    <origin xyz="0 0 0"/>
  </link>

    <!-- CHASSIS LINK -->

    <joint name="chassis_joint" type="fixed">
        <parent link="base_link"/>
        <child link="chassis"/>
        <origin xyz="0.1 0 0"/>
    </joint>

    <link name="chassis">
        <visual>
            <origin xyz="0.03 0 0.075" rpy="0 0 0"/>
            <geometry>
                <box size="0.35 0.31 0.15"/>
            </geometry>
            <material name="blue"/>
        </visual>

        <collision>
            <origin xyz="0.03 0 0.075" rpy="0 0 0"/>
            <geometry>
                <box size="0.35 0.31 0.15"/>
            </geometry>
            <material name="blue"/>
        </collision>
        <inertial>
      <mass value="5.0"/>
      <inertia ixx="0.02" ixy="0" ixz="0" iyy="0.02" iyz="0" izz="0.02"/>
    </inertial>
    </link>

        <!--left wheel-->
    <link name="left_wheel_link">
    <inertial>
      <origin xyz="0 0 0" />
      <mass value="0.01" />
      <inertia ixx="0.001" ixy="0.0" ixz="0.0" iyy="0.001" iyz="0.0" izz="0.001" />
    </inertial>

    <visual>
      <origin xyz="0 0 0" rpy="0 1.57 1.57" />
      <geometry>
        <cylinder radius="0.036" length="0.024" />
      </geometry>
      <material name="black"/>
    </visual>

    <collision>
      <origin xyz="0 0 0" rpy="0 1.57 1.57" />
      <geometry>
        <cylinder radius="0.036" length="0.024" />
      </geometry>
      <material name="black"/>
    </collision>
    </link>

   <joint name="left_wheel_joint" type="continuous">
      <origin xyz="0 0.13 0.015" rpy="0 0 0" />
      <parent link="base_link" />
      <child link="left_wheel_link" />
      <axis xyz="0 1 0" />
    </joint>

    <!--right wheel-->
    <link name="right_wheel_link">
    <inertial>
      <origin xyz="0 0 0" />
      <mass value="0.01" />
      <inertia ixx="0.001" ixy="0.0" ixz="0.0" iyy="0.001" iyz="0.0" izz="0.001" />
    </inertial>

    <visual>
      <origin xyz="0 0 0" rpy="0 1.57 1.57" />
      <geometry>
        <cylinder radius="0.036" length="0.024" />
      </geometry>
      <material name="black"/>
    </visual>
    

    <collision>
      <origin xyz="0 0 0" rpy="0 1.57 1.57" />
      <geometry>
        <cylinder radius="0.036" length="0.024" />
      </geometry>
      <material name="black"/>
    </collision>
    </link>

   <joint name="right_wheel_joint" type="continuous">
      <origin xyz="0 -0.13 0.015" rpy="0 0 0" />
      <parent link="base_link" />
      <child link="right_wheel_link" />
      <axis xyz="0 1 0" />
    </joint>


    <!-- end of wheels-->
    <link name="rear_wheel_link">
    <inertial>
      <origin xyz="0 0 0"/>
      <mass value="0.001" />
      <inertia ixx="0.0001" ixy="0.0" ixz="0.0"
        iyy="0.0001" iyz="0.0" izz="0.0001" />
    </inertial>

    <visual>
      <origin xyz="0.25 0 0" rpy="0 1.57 1.57"/>
      <geometry>
        <sphere radius="0.021" />
      </geometry>
      <material name="orange"/>
    </visual>

    <collision>
      <origin xyz="0.25 0 0" rpy="0 1.57 1.57" />
      <geometry>
        <sphere radius="0.021" />
      </geometry>
      <material name="orange"/>
    </collision>
    </link>
    <joint name="rear_castor_joint" type="fixed">
      <origin xyz="0 0 0.0" rpy="0 0 0"/>
      <parent link="base_link"/>
      <child link="rear_wheel_link"/>
      <axis xyz="0 1 0"/>
    </joint>






    <gazebo>
      <plugin name="differential_drive_controller" filename="libgazebo_ros_diff_drive.so">
        <alwaysOn>true</alwaysOn>
        <updateRate>40</updateRate>
        <leftJoint>left_wheel_joint</leftJoint>
        <rightJoint>right_wheel_joint</rightJoint>
        <wheelSeparation>0.26</wheelSeparation>
        <wheelDiameter>0.072</wheelDiameter>
        <wheelTorque>1</wheelTorque>
        <commandTopic>cmd_vel</commandTopic>
        <odometryTopic>odom</odometryTopic>
        <odometryFrame>odom</odometryFrame>
        <robotBaseFrame>base_footprint</robotBaseFrame>
      </plugin>

      <plugin name="p3d_base_controller" filename="libgazebo_ros_p3d.so">
        <alwaysOn>true</alwaysOn>
        <updateRate>100.0</updateRate>
        <bodyName>base_link</bodyName>
        <topicName>simple_controller/absolute_position</topicName>
        <gaussianNoise>0</gaussianNoise>
        <frameName>map</frameName>
        <xyzOffsets>0 0 0</xyzOffsets>
        <rpyOffsets>0 0 0</rpyOffsets>
        <!--<interface:position name="p3d_base_position"/>-->
      </plugin>
    </gazebo>

    <gazebo reference="left_wheel_link">
      <mu1>1.0</mu1>
      <mu2>1.0</mu2>
      <kp>1000000.0</kp>
      <kd>100.0</kd>
      <minDepth>0.001</minDepth>
      <maxVel>1.0</maxVel>
    </gazebo>

    <gazebo reference="right_wheel_link">
      <mu1>1.0</mu1>
      <mu2>1.0</mu2>
      <kp>1000000.0</kp>
      <kd>100.0</kd>
      <minDepth>0.001</minDepth>
      <maxVel>1.0</maxVel>
    </gazebo>
    <gazebo reference="rear_wheel_link">
      <mu1>0.0</mu1>
      <mu2>0.0</mu2>
      <kp>1000000.0</kp>
      <kd>100.0</kd>
      <minDepth>0.001</minDepth>
      <maxVel>1.0</maxVel>
    </gazebo>

    <gazebo reference="front_wheel_link">
      <mu1>0.0</mu1>
      <mu2>0.0</mu2>
      <kp>1000000.0</kp>
      <kd>100.0</kd>
      <minDepth>0.001</minDepth>
      <maxVel>1.0</maxVel>
    </gazebo>

    <!--gazebo>
      <plugin name="imu_controller" filename="libgazebo_ros_imu.so">
        <alwaysOn>true</alwaysOn>
        <updateRate>30</updateRate>
        <bodyName>gyro_link</bodyName>
        <topicName>turtlebot/imu/data</topicName>
        <serviceName>turtlebot/imu/is_calibrated</serviceName>
        <gaussianNoise>0.00000289</gaussianNoise>
        <xyzOffsets>0 0 0</xyzOffsets>
        <rpyOffsets>0 0 0</rpyOffsets>
      </plugin>
    </gazebo-->
  

    <gazebo reference="wall_sensor_link">
      <sensor type="ray" name="wall_sensor">
        <always_on>true</always_on>
        <update_rate>20.0</update_rate>
        <pose>0 0 0 0 0 0</pose>
        <visualize>false</visualize>
        <ray>
          <scan>
            <horizontal>
              <samples>1</samples>
              <resolution>1</resolution>
              <min_angle>0</min_angle>
              <max_angle>0</max_angle>
            </horizontal>
          </scan>
          <range>
            <min>0.0160</min>
            <max>0.04</max>
            <resolution>0.1</resolution>
          </range>
        </ray>
      </sensor>
    </gazebo>

 
    <gazebo reference="left_cliff_sensor_link">
      <sensor type="ray" name="left_cliff_sensor">
        <always_on>true</always_on>
        <update_rate>20.0</update_rate>
        <pose>0 0 0 0 0 0</pose>
        <visualize>false</visualize>
        <ray>
          <scan>
            <horizontal>
              <samples>1</samples>
              <resolution>1</resolution>
              <min_angle>0</min_angle>
              <max_angle>0</max_angle>
            </horizontal>
          </scan>
          <range>
            <min>0.01</min>
            <max>0.04</max>
            <resolution>0.1</resolution>
          </range>
        </ray>
      </sensor>
    </gazebo>

    <gazebo reference="right_cliff_sensor_link">
      <sensor type="ray" name="right_cliff_sensor">
        <always_on>true</always_on>
        <update_rate>20.0</update_rate>
        <pose>0 0 0 0 0 0</pose>
        <visualize>false</visualize>
        <ray>
          <scan>
            <horizontal>
              <samples>1</samples>
              <resolution>1</resolution>
              <min_angle>0</min_angle>
              <max_angle>0</max_angle>
            </horizontal>
          </scan>
          <range>
            <min>0.01</min>
            <max>0.04</max>
            <resolution>0.1</resolution>
          </range>
        </ray>
      </sensor>
    </gazebo>

    <gazebo reference="leftfront_cliff_sensor_link">
      <sensor type="ray" name="leftfront_cliff_sensor">
        <always_on>true</always_on>
        <update_rate>20.0</update_rate>
        <pose>0 0 0 0 0 0</pose>
        <visualize>false</visualize>
        <ray>
          <scan>
            <horizontal>
              <samples>1</samples>
              <resolution>1</resolution>
              <min_angle>0</min_angle>
              <max_angle>0</max_angle>
            </horizontal>
          </scan>
          <range>
            <min>0.01</min>
            <max>0.04</max>
            <resolution>0.1</resolution>
          </range>
        </ray>
      </sensor>
    </gazebo>

    <gazebo reference="rightfront_cliff_sensor_link">
      <sensor type="ray" name="rightfront_cliff_sensor">
        <always_on>true</always_on>
        <update_rate>20.0</update_rate>
        <pose>0 0 0 0 0 0</pose>
        <visualize>false</visualize>
        <ray>
          <scan>
            <horizontal>
              <samples>1</samples>
              <resolution>1</resolution>
              <min_angle>0</min_angle>
              <max_angle>0</max_angle>
            </horizontal>
          </scan>
          <range>
            <min>0.01</min>
            <max>0.04</max>
            <resolution>0.1</resolution>
          </range>
        </ray>
      </sensor>
    </gazebo>

  <gazebo>
    <plugin name="wind_plugin" filename="libgazebo_ros_wind.so">
      <robotNamespace>/robot</robotNamespace>
      <topicName>wind</topicName>
      <frameName>base_link</frameName>
      <windDirection>0 1 0</windDirection>  <!-- Wind blowing in Y direction -->
      <windForceMean>5</windForceMean>  <!-- Mean wind force -->
      <windForceVariance>1</windForceVariance>  <!-- Variance in wind force -->
    </plugin>
  </gazebo>


    <link name="laser">
    <visual>
      <geometry>
        <cylinder length="0.1" radius="0.04"/>
      </geometry>
    </visual>
  </link>

    <collision>
      <origin xyz= "0 0 0" rpy = "0 0 0"/> 
      <geometry>
        <cylinder length="0.1" radius="0.04"/>
      </geometry>
    </collision>

  <joint name="lidar_joint" type="fixed">
    <parent link="base_link"/> <!-- LIDAR'ın takılacağı bağlantı -->
    <child link="laser"/>
    <origin xyz="0.25 0 0.18" rpy="0 0 0"/>
  </joint>




  <!-- hokuyo -->
  <gazebo reference="laser">
    <sensor type="ray" name="head_hokuyo_sensor">
      <pose>0 0 0 0 0 0</pose>
      <visualize>true</visualize>
      <update_rate>10.0</update_rate>
      <ray>
        <scan>
          <horizontal>
            <samples>1080</samples>
            <resolution>1</resolution>
            <min_angle>-3.14</min_angle>
            <max_angle>3.14</max_angle>
          </horizontal>
        </scan>
        <range>
          <min>0.10</min>
          <max>6.0</max>
          <resolution>0.01</resolution>
        </range>
        <noise>
          <type>gaussian</type>
          <mean>0.0</mean>
          <stddev>0.01</stddev>
        </noise>
      </ray>
      <plugin name="gazebo_ros_head_hokuyo_controller" filename="libgazebo_ros_laser.so">
        <topicName>/scan</topicName>
        <frameName>laser</frameName>
      </plugin>
    </sensor>
  </gazebo>



<!-- differential drive plugins -->



<gazebo>
  <plugin name="differential_drive_controller" filename="libgazebo_ros_diff_drive.so">

    <!-- Plugin update rate in Hz -->
    <updateRate>10</updateRate>

    <!-- Name of left joint, defaults to `left_joint` -->
    <leftJoint>left_wheel_joint</leftJoint>

    <!-- Name of right joint, defaults to `right_joint` -->
    <rightJoint>right_wheel_joint</rightJoint>

    <!-- The distance from the center of one wheel to the other, in meters, defaults to 0.34 m -->
    <wheelSeparation>0.26</wheelSeparation>

    <!-- Diameter of the wheels, in meters, defaults to 0.15 m -->
    <wheelDiameter>0.072</wheelDiameter>

    <!-- Wheel acceleration, in rad/s^2, defaults to 0.0 rad/s^2 -->
    <wheelAcceleration>1.0</wheelAcceleration>

    <!-- Maximum torque which the wheels can produce, in Nm, defaults to 5 Nm -->
    <wheelTorque>20</wheelTorque>

    <!-- Topic to receive geometry_msgs/Twist message commands, defaults to `cmd_vel` -->
    <commandTopic>cmd_vel</commandTopic>

    <!-- Topic to publish nav_msgs/Odometry messages, defaults to `odom` -->
    <odometryTopic>odom</odometryTopic>

    <!-- Odometry frame, defaults to `odom` -->
    <odometryFrame>odom</odometryFrame>

    <!-- Robot frame to calculate odometry from, defaults to `base_footprint` -->
    <robotBaseFrame>base_link</robotBaseFrame>

    <!-- Odometry source, 0 for ENCODER, 1 for WORLD, defaults to WORLD -->
    <odometrySource>1</odometrySource>

    <!-- Set to true to publish transforms for the wheel links, defaults to false -->
    <publishWheelTF>true</publishWheelTF>

    <!-- Set to true to publish transforms for the odometry, defaults to true -->
    <publishOdom>true</publishOdom>

    <!-- Set to true to publish sensor_msgs/JointState on /joint_states for the wheel joints, defaults to false -->
    <publishWheelJointState>true</publishWheelJointState>

    <!-- Set to true to swap right and left wheels, defaults to true -->
    <legacyMode>false</legacyMode>
  </plugin>
</gazebo>


</robot>